2022-12-14 12:27:28,438 ERROR Connection issue while reading from PostgreSQL
Traceback (most recent call last):
  File "C:\Users\roman\PycharmProjects\mqtt_messages\postgre_get_data.py", line 46, in connect_now
    connect_now()
  File "C:\Users\roman\PycharmProjects\mqtt_messages\postgre_get_data.py", line 34, in connect_now
    a = int(input('Update data 1/0?'))
        ^^^^^^^^^^^^^^^^^^^^^^^^^^^^^^
ValueError: invalid literal for int() with base 10: ''
2022-12-14 12:27:38,215 INFO Запись успешно добавлена в таблицy
2022-12-14 12:28:48,227 INFO Запись успешно добавлена в таблицy
