2022-12-22 16:50:42,306 ERROR Connection issue while reading from PostgreSQL
Traceback (most recent call last):
  File "C:\Users\roman\PycharmProjects\mqtt_messages\postgre_get_data.py", line 57, in connect_now
    connect_now()
  File "C:\Users\roman\PycharmProjects\mqtt_messages\postgre_get_data.py", line 43, in connect_now
    a = int(input('Update data 1/0?'))
        ^^^^^^^^^^^^^^^^^^^^^^^^^^^^^^
ValueError: invalid literal for int() with base 10: ''
2022-12-22 16:50:45,322 INFO no new data found while check
2022-12-22 16:50:45,322 INFO no new data found while check
2022-12-22 16:50:45,322 INFO no new data found while check
2022-12-22 16:50:51,934 INFO No new data to publish
NoneType: None
2022-12-22 16:50:51,936 INFO No new data to publish
NoneType: None
2022-12-22 16:50:51,937 INFO No new data to publish
NoneType: None
2022-12-22 16:50:56,945 INFO Запись успешно добавлена в таблицy
2022-12-22 16:51:06,950 INFO Запись успешно добавлена в таблицy
2022-12-22 16:51:16,954 INFO Запись успешно добавлена в таблицy
2022-12-22 16:51:26,958 INFO Запись успешно добавлена в таблицy
2022-12-22 16:51:36,964 INFO Запись успешно добавлена в таблицy
2022-12-22 16:51:46,968 INFO Запись успешно добавлена в таблицy
2022-12-22 16:51:56,972 INFO Запись успешно добавлена в таблицy
